2020-10-02 11:23:46,370 ERROR: Exception on /checkout [GET] [in c:\users\sergio\desktop\project\venv\lib\site-packages\flask\app.py:1891]
Traceback (most recent call last):
  File "c:\users\sergio\desktop\project\venv\lib\site-packages\flask\app.py", line 2447, in wsgi_app
    response = self.full_dispatch_request()
  File "c:\users\sergio\desktop\project\venv\lib\site-packages\flask\app.py", line 1952, in full_dispatch_request
    rv = self.handle_user_exception(e)
  File "c:\users\sergio\desktop\project\venv\lib\site-packages\flask\app.py", line 1821, in handle_user_exception
    reraise(exc_type, exc_value, tb)
  File "c:\users\sergio\desktop\project\venv\lib\site-packages\flask\_compat.py", line 39, in reraise
    raise value
  File "c:\users\sergio\desktop\project\venv\lib\site-packages\flask\app.py", line 1950, in full_dispatch_request
    rv = self.dispatch_request()
  File "c:\users\sergio\desktop\project\venv\lib\site-packages\flask\app.py", line 1936, in dispatch_request
    return self.view_functions[rule.endpoint](**req.view_args)
  File "c:\users\sergio\desktop\project\venv\lib\site-packages\flask_login\utils.py", line 272, in decorated_view
    return func(*args, **kwargs)
  File "C:\Users\Sergio\Desktop\SDG Project 3\app\main\routes.py", line 201, in checkout
    if form.validate_on_submit():
UnboundLocalError: local variable 'form' referenced before assignment
2020-10-02 11:24:27,007 INFO: HomeShop startup [in C:\Users\Sergio\Desktop\SDG Project 3\app\__init__.py:94]
2020-10-02 11:24:29,743 ERROR: Exception on /checkout [GET] [in c:\users\sergio\desktop\project\venv\lib\site-packages\flask\app.py:1891]
Traceback (most recent call last):
  File "c:\users\sergio\desktop\project\venv\lib\site-packages\flask\app.py", line 2447, in wsgi_app
    response = self.full_dispatch_request()
  File "c:\users\sergio\desktop\project\venv\lib\site-packages\flask\app.py", line 1952, in full_dispatch_request
    rv = self.handle_user_exception(e)
  File "c:\users\sergio\desktop\project\venv\lib\site-packages\flask\app.py", line 1821, in handle_user_exception
    reraise(exc_type, exc_value, tb)
  File "c:\users\sergio\desktop\project\venv\lib\site-packages\flask\_compat.py", line 39, in reraise
    raise value
  File "c:\users\sergio\desktop\project\venv\lib\site-packages\flask\app.py", line 1950, in full_dispatch_request
    rv = self.dispatch_request()
  File "c:\users\sergio\desktop\project\venv\lib\site-packages\flask\app.py", line 1936, in dispatch_request
    return self.view_functions[rule.endpoint](**req.view_args)
  File "c:\users\sergio\desktop\project\venv\lib\site-packages\flask_login\utils.py", line 272, in decorated_view
    return func(*args, **kwargs)
  File "C:\Users\Sergio\Desktop\SDG Project 3\app\main\routes.py", line 214, in checkout
    order_client = CustomerOrderDetails.query.filter_by(email=user.email).first_or_404()
UnboundLocalError: local variable 'user' referenced before assignment
2020-10-02 11:25:46,608 INFO: HomeShop startup [in C:\Users\Sergio\Desktop\SDG Project 3\app\__init__.py:94]
2020-10-02 11:35:42,121 INFO: HomeShop startup [in C:\Users\Sergio\Desktop\SDG Project 3\app\__init__.py:94]
2020-10-02 11:35:48,516 ERROR: Exception on /checkout [POST] [in c:\users\sergio\desktop\project\venv\lib\site-packages\flask\app.py:1891]
Traceback (most recent call last):
  File "c:\users\sergio\desktop\project\venv\lib\site-packages\flask\app.py", line 2447, in wsgi_app
    response = self.full_dispatch_request()
  File "c:\users\sergio\desktop\project\venv\lib\site-packages\flask\app.py", line 1952, in full_dispatch_request
    rv = self.handle_user_exception(e)
  File "c:\users\sergio\desktop\project\venv\lib\site-packages\flask\app.py", line 1821, in handle_user_exception
    reraise(exc_type, exc_value, tb)
  File "c:\users\sergio\desktop\project\venv\lib\site-packages\flask\_compat.py", line 39, in reraise
    raise value
  File "c:\users\sergio\desktop\project\venv\lib\site-packages\flask\app.py", line 1950, in full_dispatch_request
    rv = self.dispatch_request()
  File "c:\users\sergio\desktop\project\venv\lib\site-packages\flask\app.py", line 1936, in dispatch_request
    return self.view_functions[rule.endpoint](**req.view_args)
  File "c:\users\sergio\desktop\project\venv\lib\site-packages\flask_login\utils.py", line 272, in decorated_view
    return func(*args, **kwargs)
  File "C:\Users\Sergio\Desktop\SDG Project 3\app\main\routes.py", line 215, in checkout
    order_item = OrderItem(order_client=order_client, customer=current_user.id, product=pro.id, prize=pro.pize, quantity=pro.quantity, ordered=True)
AttributeError: 'dict' object has no attribute 'id'
2020-10-02 11:37:47,338 INFO: HomeShop startup [in C:\Users\Sergio\Desktop\SDG Project 3\app\__init__.py:94]
2020-10-02 11:37:51,123 ERROR: Exception on /checkout [POST] [in c:\users\sergio\desktop\project\venv\lib\site-packages\flask\app.py:1891]
Traceback (most recent call last):
  File "c:\users\sergio\desktop\project\venv\lib\site-packages\flask\app.py", line 2447, in wsgi_app
    response = self.full_dispatch_request()
  File "c:\users\sergio\desktop\project\venv\lib\site-packages\flask\app.py", line 1952, in full_dispatch_request
    rv = self.handle_user_exception(e)
  File "c:\users\sergio\desktop\project\venv\lib\site-packages\flask\app.py", line 1821, in handle_user_exception
    reraise(exc_type, exc_value, tb)
  File "c:\users\sergio\desktop\project\venv\lib\site-packages\flask\_compat.py", line 39, in reraise
    raise value
  File "c:\users\sergio\desktop\project\venv\lib\site-packages\flask\app.py", line 1950, in full_dispatch_request
    rv = self.dispatch_request()
  File "c:\users\sergio\desktop\project\venv\lib\site-packages\flask\app.py", line 1936, in dispatch_request
    return self.view_functions[rule.endpoint](**req.view_args)
  File "c:\users\sergio\desktop\project\venv\lib\site-packages\flask_login\utils.py", line 272, in decorated_view
    return func(*args, **kwargs)
  File "C:\Users\Sergio\Desktop\SDG Project 3\app\main\routes.py", line 215, in checkout
    order_item = OrderItem(order_client=order_client, customer=current_user.id, product=pro.id, prize=pro.pize, quantity=pro.quantity, ordered=True)
AttributeError: 'dict' object has no attribute 'id'
2020-10-02 11:39:18,217 INFO: HomeShop startup [in C:\Users\Sergio\Desktop\SDG Project 3\app\__init__.py:94]
2020-10-02 11:39:22,727 ERROR: Exception on /checkout [POST] [in c:\users\sergio\desktop\project\venv\lib\site-packages\flask\app.py:1891]
Traceback (most recent call last):
  File "c:\users\sergio\desktop\project\venv\lib\site-packages\flask\app.py", line 2447, in wsgi_app
    response = self.full_dispatch_request()
  File "c:\users\sergio\desktop\project\venv\lib\site-packages\flask\app.py", line 1952, in full_dispatch_request
    rv = self.handle_user_exception(e)
  File "c:\users\sergio\desktop\project\venv\lib\site-packages\flask\app.py", line 1821, in handle_user_exception
    reraise(exc_type, exc_value, tb)
  File "c:\users\sergio\desktop\project\venv\lib\site-packages\flask\_compat.py", line 39, in reraise
    raise value
  File "c:\users\sergio\desktop\project\venv\lib\site-packages\flask\app.py", line 1950, in full_dispatch_request
    rv = self.dispatch_request()
  File "c:\users\sergio\desktop\project\venv\lib\site-packages\flask\app.py", line 1936, in dispatch_request
    return self.view_functions[rule.endpoint](**req.view_args)
  File "c:\users\sergio\desktop\project\venv\lib\site-packages\flask_login\utils.py", line 272, in decorated_view
    return func(*args, **kwargs)
  File "C:\Users\Sergio\Desktop\SDG Project 3\app\main\routes.py", line 215, in checkout
    order_item = OrderItem(order_client=order_client.id, customer=current_user.id, product=pro.id, prize=pro.pize, quantity=pro.quantity, ordered=True)
AttributeError: 'dict' object has no attribute 'id'
2020-10-02 11:45:29,614 INFO: HomeShop startup [in C:\Users\Sergio\Desktop\SDG Project 3\app\__init__.py:94]
2020-10-02 11:45:36,714 ERROR: Exception on /checkout [POST] [in c:\users\sergio\desktop\project\venv\lib\site-packages\flask\app.py:1891]
Traceback (most recent call last):
  File "c:\users\sergio\desktop\project\venv\lib\site-packages\flask\app.py", line 2447, in wsgi_app
    response = self.full_dispatch_request()
  File "c:\users\sergio\desktop\project\venv\lib\site-packages\flask\app.py", line 1952, in full_dispatch_request
    rv = self.handle_user_exception(e)
  File "c:\users\sergio\desktop\project\venv\lib\site-packages\flask\app.py", line 1821, in handle_user_exception
    reraise(exc_type, exc_value, tb)
  File "c:\users\sergio\desktop\project\venv\lib\site-packages\flask\_compat.py", line 39, in reraise
    raise value
  File "c:\users\sergio\desktop\project\venv\lib\site-packages\flask\app.py", line 1950, in full_dispatch_request
    rv = self.dispatch_request()
  File "c:\users\sergio\desktop\project\venv\lib\site-packages\flask\app.py", line 1936, in dispatch_request
    return self.view_functions[rule.endpoint](**req.view_args)
  File "c:\users\sergio\desktop\project\venv\lib\site-packages\flask_login\utils.py", line 272, in decorated_view
    return func(*args, **kwargs)
  File "C:\Users\Sergio\Desktop\SDG Project 3\app\main\routes.py", line 215, in checkout
    order_item = OrderItem(order_client=order_client.id, customer=current_user.id, product=pro['id'], prize=pro['prize'], quantity=pro['quantity'], ordered=True)
KeyError: 'id'
2020-10-02 11:46:55,456 INFO: HomeShop startup [in C:\Users\Sergio\Desktop\SDG Project 3\app\__init__.py:94]
