2020-10-05 14:04:08,071 ERROR: Exception on /shop//product/category/1 [GET] [in c:\users\sergio\desktop\project\venv\lib\site-packages\flask\app.py:1891]
Traceback (most recent call last):
  File "c:\users\sergio\desktop\project\venv\lib\site-packages\flask\app.py", line 1950, in full_dispatch_request
    rv = self.dispatch_request()
  File "c:\users\sergio\desktop\project\venv\lib\site-packages\flask\app.py", line 1926, in dispatch_request
    self.raise_routing_exception(req)
  File "c:\users\sergio\desktop\project\venv\lib\site-packages\flask\app.py", line 1908, in raise_routing_exception
    raise request.routing_exception
  File "c:\users\sergio\desktop\project\venv\lib\site-packages\flask\ctx.py", line 350, in match_request
    result = self.url_adapter.match(return_rule=True)
  File "c:\users\sergio\desktop\project\venv\lib\site-packages\werkzeug\routing.py", line 1945, in match
    raise NotFound()
werkzeug.exceptions.NotFound: 404 Not Found: The requested URL was not found on the server. If you entered the URL manually please check your spelling and try again.

During handling of the above exception, another exception occurred:

Traceback (most recent call last):
  File "c:\users\sergio\desktop\project\venv\lib\site-packages\flask\app.py", line 2447, in wsgi_app
    response = self.full_dispatch_request()
  File "c:\users\sergio\desktop\project\venv\lib\site-packages\flask\app.py", line 1952, in full_dispatch_request
    rv = self.handle_user_exception(e)
  File "c:\users\sergio\desktop\project\venv\lib\site-packages\flask\app.py", line 1816, in handle_user_exception
    return self.handle_http_exception(e)
  File "c:\users\sergio\desktop\project\venv\lib\site-packages\flask\app.py", line 1744, in handle_http_exception
    return handler(e)
  File "C:\Users\Sergio\Desktop\Team-668\app\errors\handlers.py", line 14, in not_found_error
    return render_template('errors/404.html'), 404
  File "c:\users\sergio\desktop\project\venv\lib\site-packages\flask\templating.py", line 137, in render_template
    return _render(
  File "c:\users\sergio\desktop\project\venv\lib\site-packages\flask\templating.py", line 120, in _render
    rv = template.render(context)
  File "c:\users\sergio\desktop\project\venv\lib\site-packages\jinja2\environment.py", line 1090, in render
    self.environment.handle_exception()
  File "c:\users\sergio\desktop\project\venv\lib\site-packages\jinja2\environment.py", line 832, in handle_exception
    reraise(*rewrite_traceback_stack(source=source))
  File "c:\users\sergio\desktop\project\venv\lib\site-packages\jinja2\_compat.py", line 28, in reraise
    raise value.with_traceback(tb)
  File "C:\Users\Sergio\Desktop\Team-668\app\templates\errors\404.html", line 1, in top-level template code
    {% extends "base2.html" %}
  File "C:\Users\Sergio\Desktop\Team-668\app\templates\base2.html", line 1, in top-level template code
    {% extends 'bootstrap/base.html' %}
  File "c:\users\sergio\desktop\project\venv\lib\site-packages\flask_bootstrap\templates\bootstrap\base.html", line 1, in top-level template code
    {% block doc -%}
  File "c:\users\sergio\desktop\project\venv\lib\site-packages\flask_bootstrap\templates\bootstrap\base.html", line 4, in block "doc"
    {%- block html %}
  File "c:\users\sergio\desktop\project\venv\lib\site-packages\flask_bootstrap\templates\bootstrap\base.html", line 20, in block "html"
    {% block body -%}
  File "C:\Users\Sergio\Desktop\Team-668\app\templates\base2.html", line 22, in block "body"
    {% include 'footer.html' %}
  File "C:\Users\Sergio\Desktop\Team-668\app\templates\footer.html", line 114, in top-level template code
    {% for c in cat1[:6] %}
jinja2.exceptions.UndefinedError: 'cat1' is undefined
2020-10-05 14:11:00,869 INFO: HomeShop startup [in C:\Users\Sergio\Desktop\Team-668\app\__init__.py:99]
2020-10-05 14:11:08,130 ERROR: Exception on /shop//product/category/1 [GET] [in c:\users\sergio\desktop\project\venv\lib\site-packages\flask\app.py:1891]
Traceback (most recent call last):
  File "c:\users\sergio\desktop\project\venv\lib\site-packages\flask\app.py", line 1950, in full_dispatch_request
    rv = self.dispatch_request()
  File "c:\users\sergio\desktop\project\venv\lib\site-packages\flask\app.py", line 1926, in dispatch_request
    self.raise_routing_exception(req)
  File "c:\users\sergio\desktop\project\venv\lib\site-packages\flask\app.py", line 1908, in raise_routing_exception
    raise request.routing_exception
  File "c:\users\sergio\desktop\project\venv\lib\site-packages\flask\ctx.py", line 350, in match_request
    result = self.url_adapter.match(return_rule=True)
  File "c:\users\sergio\desktop\project\venv\lib\site-packages\werkzeug\routing.py", line 1945, in match
    raise NotFound()
werkzeug.exceptions.NotFound: 404 Not Found: The requested URL was not found on the server. If you entered the URL manually please check your spelling and try again.

During handling of the above exception, another exception occurred:

Traceback (most recent call last):
  File "c:\users\sergio\desktop\project\venv\lib\site-packages\flask\app.py", line 2447, in wsgi_app
    response = self.full_dispatch_request()
  File "c:\users\sergio\desktop\project\venv\lib\site-packages\flask\app.py", line 1952, in full_dispatch_request
    rv = self.handle_user_exception(e)
  File "c:\users\sergio\desktop\project\venv\lib\site-packages\flask\app.py", line 1816, in handle_user_exception
    return self.handle_http_exception(e)
  File "c:\users\sergio\desktop\project\venv\lib\site-packages\flask\app.py", line 1744, in handle_http_exception
    return handler(e)
  File "C:\Users\Sergio\Desktop\Team-668\app\errors\handlers.py", line 14, in not_found_error
    return render_template('errors/404.html'), 404
  File "c:\users\sergio\desktop\project\venv\lib\site-packages\flask\templating.py", line 137, in render_template
    return _render(
  File "c:\users\sergio\desktop\project\venv\lib\site-packages\flask\templating.py", line 120, in _render
    rv = template.render(context)
  File "c:\users\sergio\desktop\project\venv\lib\site-packages\jinja2\environment.py", line 1090, in render
    self.environment.handle_exception()
  File "c:\users\sergio\desktop\project\venv\lib\site-packages\jinja2\environment.py", line 832, in handle_exception
    reraise(*rewrite_traceback_stack(source=source))
  File "c:\users\sergio\desktop\project\venv\lib\site-packages\jinja2\_compat.py", line 28, in reraise
    raise value.with_traceback(tb)
  File "C:\Users\Sergio\Desktop\Team-668\app\templates\errors\404.html", line 1, in top-level template code
    {% extends "base2.html" %}
  File "C:\Users\Sergio\Desktop\Team-668\app\templates\base2.html", line 1, in top-level template code
    {% extends 'bootstrap/base.html' %}
  File "c:\users\sergio\desktop\project\venv\lib\site-packages\flask_bootstrap\templates\bootstrap\base.html", line 1, in top-level template code
    {% block doc -%}
  File "c:\users\sergio\desktop\project\venv\lib\site-packages\flask_bootstrap\templates\bootstrap\base.html", line 4, in block "doc"
    {%- block html %}
  File "c:\users\sergio\desktop\project\venv\lib\site-packages\flask_bootstrap\templates\bootstrap\base.html", line 20, in block "html"
    {% block body -%}
  File "C:\Users\Sergio\Desktop\Team-668\app\templates\base2.html", line 22, in block "body"
    {% include 'footer.html' %}
  File "C:\Users\Sergio\Desktop\Team-668\app\templates\footer.html", line 114, in top-level template code
    {% for c in cat1[:6] %}
jinja2.exceptions.UndefinedError: 'cat1' is undefined
2020-10-05 14:11:20,363 ERROR: Exception on /shop/Spar [GET] [in c:\users\sergio\desktop\project\venv\lib\site-packages\flask\app.py:1891]
Traceback (most recent call last):
  File "c:\users\sergio\desktop\project\venv\lib\site-packages\flask\app.py", line 2447, in wsgi_app
    response = self.full_dispatch_request()
  File "c:\users\sergio\desktop\project\venv\lib\site-packages\flask\app.py", line 1952, in full_dispatch_request
    rv = self.handle_user_exception(e)
  File "c:\users\sergio\desktop\project\venv\lib\site-packages\flask\app.py", line 1821, in handle_user_exception
    reraise(exc_type, exc_value, tb)
  File "c:\users\sergio\desktop\project\venv\lib\site-packages\flask\_compat.py", line 39, in reraise
    raise value
  File "c:\users\sergio\desktop\project\venv\lib\site-packages\flask\app.py", line 1950, in full_dispatch_request
    rv = self.dispatch_request()
  File "c:\users\sergio\desktop\project\venv\lib\site-packages\flask\app.py", line 1936, in dispatch_request
    return self.view_functions[rule.endpoint](**req.view_args)
  File "C:\Users\Sergio\Desktop\Team-668\app\main\routes.py", line 163, in shop
    return render_template('shop2.html', aisles=aisles.items, form=form, next_url=next_url, prev_url=prev_url, category=category, shopname=shopname, store=store)
  File "c:\users\sergio\desktop\project\venv\lib\site-packages\flask\templating.py", line 137, in render_template
    return _render(
  File "c:\users\sergio\desktop\project\venv\lib\site-packages\flask\templating.py", line 120, in _render
    rv = template.render(context)
  File "c:\users\sergio\desktop\project\venv\lib\site-packages\jinja2\environment.py", line 1090, in render
    self.environment.handle_exception()
  File "c:\users\sergio\desktop\project\venv\lib\site-packages\jinja2\environment.py", line 832, in handle_exception
    reraise(*rewrite_traceback_stack(source=source))
  File "c:\users\sergio\desktop\project\venv\lib\site-packages\jinja2\_compat.py", line 28, in reraise
    raise value.with_traceback(tb)
  File "C:\Users\Sergio\Desktop\Team-668\app\templates\shop2.html", line 170, in top-level template code
    {% include 'footer.html' %}
  File "C:\Users\Sergio\Desktop\Team-668\app\templates\footer.html", line 114, in top-level template code
    {% for c in cat1[:6] %}
jinja2.exceptions.UndefinedError: 'cat1' is undefined
