2020-09-18 13:35:06,557 ERROR: Exception on /community [GET] [in c:\users\sergio\desktop\project\venv\lib\site-packages\flask\app.py:1891]
Traceback (most recent call last):
  File "c:\users\sergio\desktop\project\venv\lib\site-packages\flask\app.py", line 2447, in wsgi_app
    response = self.full_dispatch_request()
  File "c:\users\sergio\desktop\project\venv\lib\site-packages\flask\app.py", line 1952, in full_dispatch_request
    rv = self.handle_user_exception(e)
  File "c:\users\sergio\desktop\project\venv\lib\site-packages\flask\app.py", line 1821, in handle_user_exception
    reraise(exc_type, exc_value, tb)
  File "c:\users\sergio\desktop\project\venv\lib\site-packages\flask\_compat.py", line 39, in reraise
    raise value
  File "c:\users\sergio\desktop\project\venv\lib\site-packages\flask\app.py", line 1950, in full_dispatch_request
    rv = self.dispatch_request()
  File "c:\users\sergio\desktop\project\venv\lib\site-packages\flask\app.py", line 1936, in dispatch_request
    return self.view_functions[rule.endpoint](**req.view_args)
  File "C:\Users\Sergio\Desktop\SDG Project 2\app\main\routes.py", line 34, in community
    posts = current_user.followed_posts().paginate(
  File "c:\users\sergio\desktop\project\venv\lib\site-packages\werkzeug\local.py", line 347, in __getattr__
    return getattr(self._get_current_object(), name)
AttributeError: 'AnonymousUserMixin' object has no attribute 'followed_posts'
2020-09-18 13:35:47,042 INFO: HomeShop startup [in C:\Users\Sergio\Desktop\SDG Project 2\app\__init__.py:84]
2020-09-18 13:35:48,709 ERROR: Exception on /community [GET] [in c:\users\sergio\desktop\project\venv\lib\site-packages\flask\app.py:1891]
Traceback (most recent call last):
  File "c:\users\sergio\desktop\project\venv\lib\site-packages\flask\app.py", line 2447, in wsgi_app
    response = self.full_dispatch_request()
  File "c:\users\sergio\desktop\project\venv\lib\site-packages\flask\app.py", line 1952, in full_dispatch_request
    rv = self.handle_user_exception(e)
  File "c:\users\sergio\desktop\project\venv\lib\site-packages\flask\app.py", line 1821, in handle_user_exception
    reraise(exc_type, exc_value, tb)
  File "c:\users\sergio\desktop\project\venv\lib\site-packages\flask\_compat.py", line 39, in reraise
    raise value
  File "c:\users\sergio\desktop\project\venv\lib\site-packages\flask\app.py", line 1950, in full_dispatch_request
    rv = self.dispatch_request()
  File "c:\users\sergio\desktop\project\venv\lib\site-packages\flask\app.py", line 1936, in dispatch_request
    return self.view_functions[rule.endpoint](**req.view_args)
  File "C:\Users\Sergio\Desktop\SDG Project 2\app\main\routes.py", line 34, in community
    posts = current_user.followed_posts().paginate(
  File "c:\users\sergio\desktop\project\venv\lib\site-packages\werkzeug\local.py", line 347, in __getattr__
    return getattr(self._get_current_object(), name)
AttributeError: 'AnonymousUserMixin' object has no attribute 'followed_posts'
2020-09-18 13:35:52,722 ERROR: Exception on /community [GET] [in c:\users\sergio\desktop\project\venv\lib\site-packages\flask\app.py:1891]
Traceback (most recent call last):
  File "c:\users\sergio\desktop\project\venv\lib\site-packages\flask\app.py", line 2447, in wsgi_app
    response = self.full_dispatch_request()
  File "c:\users\sergio\desktop\project\venv\lib\site-packages\flask\app.py", line 1952, in full_dispatch_request
    rv = self.handle_user_exception(e)
  File "c:\users\sergio\desktop\project\venv\lib\site-packages\flask\app.py", line 1821, in handle_user_exception
    reraise(exc_type, exc_value, tb)
  File "c:\users\sergio\desktop\project\venv\lib\site-packages\flask\_compat.py", line 39, in reraise
    raise value
  File "c:\users\sergio\desktop\project\venv\lib\site-packages\flask\app.py", line 1950, in full_dispatch_request
    rv = self.dispatch_request()
  File "c:\users\sergio\desktop\project\venv\lib\site-packages\flask\app.py", line 1936, in dispatch_request
    return self.view_functions[rule.endpoint](**req.view_args)
  File "C:\Users\Sergio\Desktop\SDG Project 2\app\main\routes.py", line 34, in community
    posts = current_user.followed_posts().paginate(
  File "c:\users\sergio\desktop\project\venv\lib\site-packages\werkzeug\local.py", line 347, in __getattr__
    return getattr(self._get_current_object(), name)
AttributeError: 'AnonymousUserMixin' object has no attribute 'followed_posts'
2020-09-18 13:41:12,863 INFO: HomeShop startup [in C:\Users\Sergio\Desktop\SDG Project 2\app\__init__.py:84]
2020-09-20 09:09:14,903 INFO: HomeShop startup [in C:\Users\Sergio\Desktop\SDG Project 2\app\__init__.py:84]
2020-09-21 10:37:47,705 INFO: HomeShop startup [in C:\Users\Sergio\Desktop\SDG Project 2\app\__init__.py:85]
2020-09-21 10:51:50,831 INFO: HomeShop startup [in C:\Users\Sergio\Desktop\SDG Project 2\app\__init__.py:85]
2020-09-21 10:51:52,474 ERROR: Exception on / [GET] [in c:\users\sergio\desktop\project\venv\lib\site-packages\flask\app.py:1891]
Traceback (most recent call last):
  File "c:\users\sergio\desktop\project\venv\lib\site-packages\flask\app.py", line 2447, in wsgi_app
    response = self.full_dispatch_request()
  File "c:\users\sergio\desktop\project\venv\lib\site-packages\flask\app.py", line 1952, in full_dispatch_request
    rv = self.handle_user_exception(e)
  File "c:\users\sergio\desktop\project\venv\lib\site-packages\flask\app.py", line 1821, in handle_user_exception
    reraise(exc_type, exc_value, tb)
  File "c:\users\sergio\desktop\project\venv\lib\site-packages\flask\_compat.py", line 39, in reraise
    raise value
  File "c:\users\sergio\desktop\project\venv\lib\site-packages\flask\app.py", line 1948, in full_dispatch_request
    rv = self.preprocess_request()
  File "c:\users\sergio\desktop\project\venv\lib\site-packages\flask\app.py", line 2242, in preprocess_request
    rv = func()
  File "C:\Users\Sergio\Desktop\SDG Project 2\app\main\routes.py", line 22, in before_request
    g.locale = str(get_locale())
NameError: name 'get_locale' is not defined
2020-09-21 10:52:47,605 ERROR: Exception on /index [GET] [in c:\users\sergio\desktop\project\venv\lib\site-packages\flask\app.py:1891]
Traceback (most recent call last):
  File "c:\users\sergio\desktop\project\venv\lib\site-packages\flask\app.py", line 2447, in wsgi_app
    response = self.full_dispatch_request()
  File "c:\users\sergio\desktop\project\venv\lib\site-packages\flask\app.py", line 1952, in full_dispatch_request
    rv = self.handle_user_exception(e)
  File "c:\users\sergio\desktop\project\venv\lib\site-packages\flask\app.py", line 1821, in handle_user_exception
    reraise(exc_type, exc_value, tb)
  File "c:\users\sergio\desktop\project\venv\lib\site-packages\flask\_compat.py", line 39, in reraise
    raise value
  File "c:\users\sergio\desktop\project\venv\lib\site-packages\flask\app.py", line 1948, in full_dispatch_request
    rv = self.preprocess_request()
  File "c:\users\sergio\desktop\project\venv\lib\site-packages\flask\app.py", line 2242, in preprocess_request
    rv = func()
  File "C:\Users\Sergio\Desktop\SDG Project 2\app\main\routes.py", line 22, in before_request
    g.locale = str(get_locale())
NameError: name 'get_locale' is not defined
2020-09-21 10:55:30,502 INFO: HomeShop startup [in C:\Users\Sergio\Desktop\SDG Project 2\app\__init__.py:85]
2020-09-21 10:55:32,725 ERROR: Exception on / [GET] [in c:\users\sergio\desktop\project\venv\lib\site-packages\flask\app.py:1891]
Traceback (most recent call last):
  File "c:\users\sergio\desktop\project\venv\lib\site-packages\flask\app.py", line 2447, in wsgi_app
    response = self.full_dispatch_request()
  File "c:\users\sergio\desktop\project\venv\lib\site-packages\flask\app.py", line 1952, in full_dispatch_request
    rv = self.handle_user_exception(e)
  File "c:\users\sergio\desktop\project\venv\lib\site-packages\flask\app.py", line 1821, in handle_user_exception
    reraise(exc_type, exc_value, tb)
  File "c:\users\sergio\desktop\project\venv\lib\site-packages\flask\_compat.py", line 39, in reraise
    raise value
  File "c:\users\sergio\desktop\project\venv\lib\site-packages\flask\app.py", line 1948, in full_dispatch_request
    rv = self.preprocess_request()
  File "c:\users\sergio\desktop\project\venv\lib\site-packages\flask\app.py", line 2242, in preprocess_request
    rv = func()
  File "C:\Users\Sergio\Desktop\SDG Project 2\app\main\routes.py", line 23, in before_request
    g.locale = str(get_locale())
  File "c:\users\sergio\desktop\project\venv\lib\site-packages\flask_babel\__init__.py", line 247, in get_locale
    babel = current_app.extensions['babel']
KeyError: 'babel'
2020-09-21 10:59:50,572 INFO: HomeShop startup [in C:\Users\Sergio\Desktop\SDG Project 2\app\__init__.py:88]
2020-09-21 11:01:14,547 INFO: HomeShop startup [in C:\Users\Sergio\Desktop\SDG Project 2\app\__init__.py:88]
2020-09-21 11:02:15,327 INFO: HomeShop startup [in C:\Users\Sergio\Desktop\SDG Project 2\app\__init__.py:88]
2020-09-21 11:12:45,243 INFO: HomeShop startup [in C:\Users\Sergio\Desktop\SDG Project 2\app\__init__.py:88]
2020-09-21 11:14:25,756 INFO: HomeShop startup [in C:\Users\Sergio\Desktop\SDG Project 2\app\__init__.py:88]
2020-09-21 11:20:15,895 INFO: HomeShop startup [in C:\Users\Sergio\Desktop\SDG Project 2\app\__init__.py:88]
2020-09-21 11:21:18,559 INFO: HomeShop startup [in C:\Users\Sergio\Desktop\SDG Project 2\app\__init__.py:88]
2020-09-21 16:43:01,374 INFO: HomeShop startup [in C:\Users\Sergio\Desktop\SDG Project 2\app\__init__.py:88]
2020-09-21 16:52:40,364 INFO: HomeShop startup [in C:\Users\Sergio\Desktop\SDG Project 2\app\__init__.py:88]
